go/tests/test_20240228164008.in
50
0-49 o
0 B 1 META 2705 30
0 S 2 GOOGL 3260 1
0 C 1
0 S 3 AMZN 2701 25
0 B 4 GOOGL 3290 10
0 C 2
1 B 5 GOOGL 2705 30
1 S 6 META 3260 1
1 C 5
1 S 7 NFLX 2701 25
1 B 8 NFLX 3290 10
1 C 6
2 B 9 NFLX 2705 30
2 S 10 NFLX 3260 1
2 C 9
2 S 11 AMZN 2701 25
2 B 12 NFLX 3290 10
2 C 10
3 B 13 GOOGL 2705 30
3 S 14 NFLX 3260 1
3 C 13
3 S 15 GOOGL 2701 25
3 B 16 AMZN 3290 10
3 C 14
4 B 17 NFLX 2705 30
4 S 18 AAPL 3260 1
4 C 17
4 S 19 NFLX 2701 25
4 B 20 META 3290 10
4 C 18
5 B 21 META 2705 30
5 S 22 GOOGL 3260 1
5 C 21
5 S 23 META 2701 25
5 B 24 NFLX 3290 10
5 C 22
6 B 25 AMZN 2705 30
6 S 26 NFLX 3260 1
6 C 25
6 S 27 AAPL 2701 25
6 B 28 META 3290 10
6 C 26
7 B 29 META 2705 30
7 S 30 GOOGL 3260 1
7 C 29
7 S 31 GOOGL 2701 25
7 B 32 GOOGL 3290 10
7 C 30
8 B 33 GOOGL 2705 30
8 S 34 AMZN 3260 1
8 C 33
8 S 35 AMZN 2701 25
8 B 36 NFLX 3290 10
8 C 34
9 B 37 AMZN 2705 30
9 S 38 NFLX 3260 1
9 C 37
9 S 39 GOOGL 2701 25
9 B 40 META 3290 10
9 C 38
10 B 41 META 2705 30
10 S 42 META 3260 1
10 C 41
10 S 43 AMZN 2701 25
10 B 44 GOOGL 3290 10
10 C 42
11 B 45 AMZN 2705 30
11 S 46 AAPL 3260 1
11 C 45
11 S 47 NFLX 2701 25
11 B 48 GOOGL 3290 10
11 C 46
12 B 49 NFLX 2705 30
12 S 50 AAPL 3260 1
12 C 49
12 S 51 META 2701 25
12 B 52 NFLX 3290 10
12 C 50
13 B 53 NFLX 2705 30
13 S 54 AMZN 3260 1
13 C 53
13 S 55 AMZN 2701 25
13 B 56 AAPL 3290 10
13 C 54
14 B 57 GOOGL 2705 30
14 S 58 NFLX 3260 1
14 C 57
14 S 59 GOOGL 2701 25
14 B 60 NFLX 3290 10
14 C 58
15 B 61 META 2705 30
15 S 62 META 3260 1
15 C 61
15 S 63 META 2701 25
15 B 64 GOOGL 3290 10
15 C 62
16 B 65 GOOGL 2705 30
16 S 66 META 3260 1
16 C 65
16 S 67 AAPL 2701 25
16 B 68 AMZN 3290 10
16 C 66
17 B 69 NFLX 2705 30
17 S 70 GOOGL 3260 1
17 C 69
17 S 71 META 2701 25
17 B 72 NFLX 3290 10
17 C 70
18 B 73 AAPL 2705 30
18 S 74 GOOGL 3260 1
18 C 73
18 S 75 AAPL 2701 25
18 B 76 META 3290 10
18 C 74
19 B 77 NFLX 2705 30
19 S 78 NFLX 3260 1
19 C 77
19 S 79 META 2701 25
19 B 80 NFLX 3290 10
19 C 78
20 B 81 AMZN 2705 30
20 S 82 META 3260 1
20 C 81
20 S 83 META 2701 25
20 B 84 GOOGL 3290 10
20 C 82
21 B 85 AMZN 2705 30
21 S 86 NFLX 3260 1
21 C 85
21 S 87 AMZN 2701 25
21 B 88 GOOGL 3290 10
21 C 86
22 B 89 GOOGL 2705 30
22 S 90 AMZN 3260 1
22 C 89
22 S 91 GOOGL 2701 25
22 B 92 AMZN 3290 10
22 C 90
23 B 93 NFLX 2705 30
23 S 94 AAPL 3260 1
23 C 93
23 S 95 GOOGL 2701 25
23 B 96 AMZN 3290 10
23 C 94
24 B 97 GOOGL 2705 30
24 S 98 NFLX 3260 1
24 C 97
24 S 99 META 2701 25
24 B 100 AAPL 3290 10
24 C 98
25 B 101 AMZN 2705 30
25 S 102 AMZN 3260 1
25 C 101
25 S 103 AAPL 2701 25
25 B 104 AMZN 3290 10
25 C 102
26 B 105 AMZN 2705 30
26 S 106 META 3260 1
26 C 105
26 S 107 GOOGL 2701 25
26 B 108 GOOGL 3290 10
26 C 106
27 B 109 AAPL 2705 30
27 S 110 GOOGL 3260 1
27 C 109
27 S 111 AAPL 2701 25
27 B 112 AAPL 3290 10
27 C 110
28 B 113 META 2705 30
28 S 114 NFLX 3260 1
28 C 113
28 S 115 GOOGL 2701 25
28 B 116 NFLX 3290 10
28 C 114
29 B 117 AMZN 2705 30
29 S 118 NFLX 3260 1
29 C 117
29 S 119 GOOGL 2701 25
29 B 120 AAPL 3290 10
29 C 118
30 B 121 AAPL 2705 30
30 S 122 META 3260 1
30 C 121
30 S 123 META 2701 25
30 B 124 AMZN 3290 10
30 C 122
31 B 125 GOOGL 2705 30
31 S 126 AAPL 3260 1
31 C 125
31 S 127 AMZN 2701 25
31 B 128 GOOGL 3290 10
31 C 126
32 B 129 META 2705 30
32 S 130 META 3260 1
32 C 129
32 S 131 AAPL 2701 25
32 B 132 NFLX 3290 10
32 C 130
33 B 133 AMZN 2705 30
33 S 134 GOOGL 3260 1
33 C 133
33 S 135 NFLX 2701 25
33 B 136 AMZN 3290 10
33 C 134
34 B 137 NFLX 2705 30
34 S 138 AMZN 3260 1
34 C 137
34 S 139 AAPL 2701 25
34 B 140 GOOGL 3290 10
34 C 138
35 B 141 META 2705 30
35 S 142 GOOGL 3260 1
35 C 141
35 S 143 META 2701 25
35 B 144 GOOGL 3290 10
35 C 142
36 B 145 META 2705 30
36 S 146 META 3260 1
36 C 145
36 S 147 AMZN 2701 25
36 B 148 META 3290 10
36 C 146
37 B 149 GOOGL 2705 30
37 S 150 AAPL 3260 1
37 C 149
37 S 151 META 2701 25
37 B 152 AAPL 3290 10
37 C 150
38 B 153 META 2705 30
38 S 154 AAPL 3260 1
38 C 153
38 S 155 GOOGL 2701 25
38 B 156 AMZN 3290 10
38 C 154
39 B 157 GOOGL 2705 30
39 S 158 GOOGL 3260 1
39 C 157
39 S 159 META 2701 25
39 B 160 AAPL 3290 10
39 C 158
40 B 161 NFLX 2705 30
40 S 162 META 3260 1
40 C 161
40 S 163 AAPL 2701 25
40 B 164 META 3290 10
40 C 162
41 B 165 GOOGL 2705 30
41 S 166 NFLX 3260 1
41 C 165
41 S 167 NFLX 2701 25
41 B 168 AMZN 3290 10
41 C 166
42 B 169 NFLX 2705 30
42 S 170 AMZN 3260 1
42 C 169
42 S 171 AAPL 2701 25
42 B 172 META 3290 10
42 C 170
43 B 173 GOOGL 2705 30
43 S 174 AMZN 3260 1
43 C 173
43 S 175 AAPL 2701 25
43 B 176 AMZN 3290 10
43 C 174
44 B 177 NFLX 2705 30
44 S 178 AAPL 3260 1
44 C 177
44 S 179 GOOGL 2701 25
44 B 180 GOOGL 3290 10
44 C 178
45 B 181 GOOGL 2705 30
45 S 182 AMZN 3260 1
45 C 181
45 S 183 META 2701 25
45 B 184 NFLX 3290 10
45 C 182
46 B 185 AAPL 2705 30
46 S 186 GOOGL 3260 1
46 C 185
46 S 187 AAPL 2701 25
46 B 188 META 3290 10
46 C 186
47 B 189 NFLX 2705 30
47 S 190 AMZN 3260 1
47 C 189
47 S 191 AAPL 2701 25
47 B 192 GOOGL 3290 10
47 C 190
48 B 193 AMZN 2705 30
48 S 194 AAPL 3260 1
48 C 193
48 S 195 GOOGL 2701 25
48 B 196 AAPL 3290 10
48 C 194
49 B 197 AMZN 2705 30
49 S 198 AMZN 3260 1
49 C 197
49 S 199 GOOGL 2701 25
49 B 200 AAPL 3290 10
49 C 198
.
0-49 x
